Workbook

Sheet Inputs
A1: One release · inputs
A2: Blue cells on yellow are yours to fill. Everything else in this workbook is a formula. Set mechanic to draw to see the LE versions, and window to 48 hours or one week for the TL flow.
A3: Field | B3: Value | C3: What it is
A4: artist | B4: Joel Mesler | C4: full name: the works are 'by' this name
A5: collab_with | B5: Joel Mesler | C5: the words after 'collaboration with': usually the name, or the estate
A6: handle | B6: joelmesler | C6: Instagram handle, blank if none
A7: x_handle | C7: X (Twitter) handle, blank if none
A8: link | B8: https://avantarte.co/joel-mesler-x | C8: the release's short link, for tweets
A9: hashtag | C9: announcement post only; blank for none
A10: ordinal | B10: debut | C10: debut, latest or second
A11: title_1 | B11: I Love You | C11: exactly as it appears, and what the card is headed with. Untitled works from a series still keep their own titles here
A12: title_2 | C12: for a pair or a trio with their own titles; blank otherwise
A13: title_3 | C13: blank otherwise. More than three titled works: give the set a collective title, or use the templates
A14: series_name | C14: set it to name the works by their series in the prose, for untitled works; the cards keep their own titles. Blank otherwise
A15: edition_phrase | B15: a new limited edition print in four colourways | C15: e.g. a new limited edition print; a quartet of new limited edition embroideries; a new limited edition print in four colourways
A16: works | B16: 1 | C16: number of artworks: sets the plural wording
A17: unit | B17: print | C17: what one is called: print, embroidery, sculpture, edition
A18: mechanic | B18: timed | C18: timed (TL) or draw (LE)
A19: window | B19: 48 hours | C19: 48 hours or one week; timed only
A20: launch_at | B20: 46162.708 | C20: date and time the window opens, or the draw opens (UK)
A21: closes_at | B21: 46164.708 | C21: date and time the window or draw closes (UK)
A22: beneficiary | C22: as it reads mid-sentence; blank if none
A23: beneficiary_handle | C23: blank if none
A24: advisor | B24: Sam | C24: signs the Insiders email and the first-time collector survey: Sofiya, Curtis or Sam
A25: early_access_code | B25: 000-000 | C25: draw releases
A26: framing_code | B26: Joel-0526-10 | C26: first-purchase framing offer code, e.g. Freud-0426-10; blank for no offer
A27: framing_percent | B27: 10 | C27: 10 or 20
A28: feature_1 | B28: Signed by the artist | C28: the standard three; clear a cell to drop it
A29: feature_2 | B29: Individually numbered
A30: feature_3 | B30: Free worldwide shipping
A31: feature_4 | B31: Available in four colourways | C31: bespoke, e.g. Hand-finished by the artist. Never 'our'.
A32: feature_5 | C32: bespoke, e.g. Available individually or as a set
A34: Fragments, written once per release. No we or our: the sheet adds our where a line needs it.
A35: bio | B35: Joel Mesler is a Los Angeles-born, New York-based painter known for vivid colours and candid text-based works that merge personal memory with pop culture. His practice is built on radical directness, drawing statements and imagery straight from his own memory and emotion. | C35: 2 to 3 sentences on the artist, third person, no handle. Coming Soon post only.
A36: hook | B36: I Love You is a declaration of love in four colourways, the colour of the text changing across the quartet. Drawing on personal memory and popular culture in equal measure, the work is disarmingly direct, and the title leaves no doubt. | C36: 2 to 3 sentences about the work. Write it as editorially as you like; the one test is that it must read as well in the middle of an email as at the top of a post. Self-contained, no rhetorical question, the artist by surname only (the frame has used the full name), one dash at most and never a pair. It reaches 16 slots, so it is the one fragment that must stand alone.
A37: qualifier | C37: a few words after the edition phrase in the email opener, e.g. spanning five decades of the artist's career. Ten words at most, a phrase not a sentence, no we or our, no artist name. Ignored when there is a beneficiary: 'released in support of X' fills the same opening. With several works the title drops out of this line, and that is what it is for.
A38: opener | C38: or the announcement's first sentence written whole, e.g. Surveillance and defiance bubble to the surface in a new limited edition silkscreen print by Ai Weiwei. Blank keeps the framed line. One sentence, the artist in full, the words limited edition. The four other emails keep the framed line either way; if this leaves out the beneficiary, the features list names it.
A39: making | B39: Created in close collaboration with the artist by printmakers at Make-Ready, the edition unites a 9-colour split fountain silkscreen with an archival pigment overlay, metallic shimmer and high-gloss varnish. | C39: one sentence on how the edition was made; write 'printmakers at Make-Ready' and the sheet adds 'our'.
A40: card_line_1 | B40: Three words, as direct as Mesler gets, in a 9-colour split fountain silkscreen finished with metallic shimmer and high-gloss varnish, in a choice of four colourways. | C40: one sentence on the first work, 15 to 30 words, under its card in six emails. With several works, say something different about each: the edition is described above the cards, so do not call each one a limited edition print.
A41: card_line_2 | C41: the second titled work; blank otherwise
...

Sheet Lines
A1: The fixed sentences, with the placeholders they take
A2: This is the whole system's copy, for the posts, the tweets and the emails. Edit a blue cell to change every future release. Column C fills the placeholders from Inputs.
A3: Key | B3: Line, with placeholders | C3: Filled from Inputs
A4: POSTS
A5: post · coming soon · status | B5: Our {ordinal} collaboration is on the horizon. | C5: =SUBSTITUTE(B5,"{ordinal}",Inputs!$B$10)
A6: post · announce · status | B6: Announcing {work}, {edition_phrase} by {named}. | C6: =SUBSTITUTE(SUBSTITUTE(SUBSTITUTE(B6,"{named}",Inputs!$B$46),"{work}",Inputs!$B$50),"{edition_phrase}",Inputs!$B$15)
A7: post · announce · status, series | B7: Announcing {edition_phrase} by {named}, from {work}. | C7: =SUBSTITUTE(SUBSTITUTE(SUBSTITUTE(B7,"{named}",Inputs!$B$46),"{work}",Inputs!$B$50),"{edition_phrase}",Inputs!$B$15)
A8: post · sustain · status | B8: A closer look at {work}, {edition_phrase} by {named}. | C8: =SUBSTITUTE(SUBSTITUTE(SUBSTITUTE(B8,"{named}",Inputs!$B$46),"{work}",Inputs!$B$50),"{edition_phrase}",Inputs!$B$15)
A9: post · artist's words · status | B9: “{quote}” – {artist} | C9: =SUBSTITUTE(SUBSTITUTE(B9,"{artist}",Inputs!$B$4),"{quote}",Inputs!$B$43)
A10: post · artist's words · second line | B10: {Work}, {edition_phrase} by {named}. | C10: =SUBSTITUTE(SUBSTITUTE(SUBSTITUTE(B10,"{named}",Inputs!$B$46),"{Work}",Inputs!$B$51),"{edition_phrase}",Inputs!$B$15)
A11: post · live · status | B11: {Work} by {named} is now available to collect, for {window} only. | C11: =SUBSTITUTE(SUBSTITUTE(SUBSTITUTE(B11,"{named}",Inputs!$B$46),"{Work}",Inputs!$B$51),"{window}",Inputs!$B$19)
A12: post · still time · status | B12: There's still time to collect {work} by {named}. | C12: =SUBSTITUTE(SUBSTITUTE(B12,"{named}",Inputs!$B$46),"{work}",Inputs!$B$50)
A13: post · last chance · status | B13: Last chance to collect {work} by {named}. | C13: =SUBSTITUTE(SUBSTITUTE(B13,"{named}",Inputs!$B$46),"{work}",Inputs!$B$50)
A14: post · last chance · status, draw | B14: Last chance to enter the draw for {work} by {named}. | C14: =SUBSTITUTE(SUBSTITUTE(B14,"{named}",Inputs!$B$46),"{work}",Inputs!$B$50)
A15: post · features line | B15: {features} | C15: =SUBSTITUTE(B15,"{features}",Inputs!$B$61)
A16: post · beneficiary line | B16: Released in support of {beneficiary_tagged}. | C16: =SUBSTITUTE(B16,"{beneficiary_tagged}",Inputs!$B$57)
A17: post · action before launch, timed | B17: Available for {window} from {launch_time} on {launch_date}. Link in bio to get updates. | C17: =SUBSTITUTE(SUBSTITUTE(SUBSTITUTE(B17,"{window}",Inputs!$B$19),"{launch_date}",Inputs!$B$66),"{launch_time}",Inputs!$B$67)
A18: post · action before launch, draw | B18: Enter the draw via our link in bio. Closes {close_date} at {close_time}. | C18: =SUBSTITUTE(SUBSTITUTE(B18,"{close_date}",Inputs!$B$70),"{close_time}",Inputs!$B$71)
A19: post · action while open, timed | B19: Link in bio to buy {a_unit}. Closes {close_date} at {close_time}. | C19: =SUBSTITUTE(SUBSTITUTE(SUBSTITUTE(B19,"{a_unit}",Inputs!$B$49),"{close_date}",Inputs!$B$70),"{close_time}",Inputs!$B$71)
A20: post · action while open, draw | B20: Enter the draw via our link in bio. Closes {close_date} at {close_time}. | C20: =SUBSTITUTE(SUBSTITUTE(B20,"{close_date}",Inputs!$B$70),"{close_time}",Inputs!$B$71)
A21: post · coming soon · action | B21: Link in bio to get updates. | C21: =B21
A22: post · hashtag | B22: #{hashtag} | C22: =SUBSTITUTE(B22,"{hashtag}",Inputs!$B$9)
A23: TWEETS
A24: tweet · coming soon · status | B24: Our {ordinal} collaboration with {collab_x} is on the horizon. | C24: =SUBSTITUTE(SUBSTITUTE(B24,"{collab_x}",Inputs!$B$48),"{ordinal}",Inputs!$B$10)
A25: tweet · coming soon · action | B25: Sign up for updates: {link} | C25: =SUBSTITUTE(B25,"{link}",Inputs!$B$8)
A26: tweet · announce · status | B26: Announcing {work}, {edition_phrase} by {named_x}{tweet_beneficiary}. | C26: =SUBSTITUTE(SUBSTITUTE(SUBSTITUTE(SUBSTITUTE(B26,"{named_x}",Inputs!$B$47),"{work}",Inputs!$B$50),"{tweet_beneficiary}",Inputs!$B$56),"{edition_phrase}",Inputs!$B$15)
A27: tweet · announce · status, series | B27: Announcing {edition_phrase} by {named_x}, from {work}{tweet_beneficiary}. | C27: =SUBSTITUTE(SUBSTITUTE(SUBSTITUTE(SUBSTITUTE(B27,"{named_x}",Inputs!$B$47),"{work}",Inputs!$B$50),"{tweet_beneficiary}",Inputs!$B$56),"{edition_phrase}",Inputs!$B$15)
A28: tweet · action before launch, timed | B28: Launches {launch_date} at {launch_time} for {window}. Sign up for updates: {link} | C28: =SUBSTITUTE(SUBSTITUTE(SUBSTITUTE(SUBSTITUTE(B28,"{link}",Inputs!$B$8),"{window}",Inputs!$B$19),"{launch_date}",Inputs!$B$66),"{launch_time}",Inputs!$B$67)
A29: tweet · action, draw | B29: Closes {close_date} at {close_time}. Enter the draw: {link} | C29: =SUBSTITUTE(SUBSTITUTE(SUBSTITUTE(B29,"{link}",Inputs!$B$8),"{close_date}",Inputs!$B$70),"{close_time}",Inputs!$B$71)
A30: tweet · action while open, timed | B30: Closes {close_date} at {close_time}. Buy {a_unit}: {link} | C30: =SUBSTITUTE(SUBSTITUTE(SUBSTITUTE(SUBSTITUTE(B30,"{link}",Inputs!$B$8),"{a_unit}",Inputs!$B$49),"{close_date}",Inputs!$B$70),"{close_time}",Inputs!$B$71)
A31: EMAILS · shared
A32: email · greeting | B32: Hi {{ personalization_token('contact.firstname', 'there') }}, | C32: =B32
A33: email · questions line | B33: If you have any questions, please don't hesitate to get in touch by replying to this email. | C33: =B33
A34: email · draw line | B34: Enter the draw for a chance to collect. Closes at {close_time} on {close_date}. | C34: =SUBSTITUTE(SUBSTITUTE(B34,"{close_date}",Inputs!$B$70),"{close_time}",Inputs!$B$71)
A35: email · edition numbers line | B35: Earlier orders will typically receive a lower edition number, with framed editions receiving lower edition numbers than unframed prints. You can read more on how we allocate edition numbers across a release here. | C35: =B35
A36: email · kicker · collect | B36: Collect {a_unit} by {artist} | C36: =SUBSTITUTE(SUBSTITUTE(B36,"{artist}",Inputs!$B$4),"{a_unit}",Inputs!$B$49)
A37: email · framing offer · welcome | B37: As a welcome gesture, enjoy {framing_percent}% off our in-house framing on your first purchase using the code {framing_code} at checkout. | C37: =SUBSTITUTE(SUBSTITUTE(B37,"{framing_code}",Inputs!$B$26),"{framing_percent}",Inputs!$B$27)
A38: email · framing offer · reminder | B38: As a reminder, you can enjoy {framing_percent}% off our in-house framing on your first purchase using the code {framing_code} at checkout. | C38: =SUBSTITUTE(SUBSTITUTE(B38,"{framing_code}",Inputs!$B$26),"{framing_percent}",Inputs!$B$27)
A39: EMAILS · announcement
A40: email · announce · subject | B40: {artist} – {edition_phrase_cap} | C40: =SUBSTITUTE(SUBSTITUTE(B40,"{artist}",Inputs!$B$4),"{edition_phrase_cap}",Inputs!$B$75)
...

Sheet Posts
A1: The posts, assembled
A2: Every cell below is a formula over Inputs and Lines. Skeleton: status line · substance · features line · action line · hashtag. Coming Soon opens with the bio. The Insiders account posts the same caption; Channels says which.
A3: # | B3: Post | C3: Channels | D3: Made of | E3: Status line | F3: Substance | G3: Features line | H3: Action line | I3: Hashtag | J3: Caption | K3: Characters
A4: 1 | B4: coming soon | C4: Main | D4: bio · status · action | E4: =Lines!$C$5 | F4: =Inputs!$B$58 | G4: ="" | H4: =Lines!$C$21 | I4: ="" | J4: =F4&IF(E4="","",CHAR(10)&CHAR(10)&E4)&IF(H4="","",CHAR(10)&CHAR(10)&H4) | K4: =LEN(J4)
A5: 2 | B5: announce | C5: Main + Insiders | D5: status · hook · features + beneficiary · action · hashtag | E5: =IF(Inputs!$B$14<>"",Lines!$C$7,Lines!$C$6) | F5: =Inputs!$B$36 | G5: =Lines!$C$15&IF(Inputs!$B$59,"",IF(Inputs!$B$57="",""," "&Lines!$C$16)) | H5: =IF(Inputs!$B$18="draw",Lines!$C$18,Lines!$C$17) | I5: =IF(Inputs!$B$9="","",Lines!$C$22) | J5: =E5&IF(F5="","",CHAR(10)&CHAR(10)&F5)&IF(G5="","",CHAR(10)&CHAR(10)&G5)&IF(H5="","",CHAR(10)&CHAR(10)&H5)&IF(I5="","",CHAR(10)&CHAR(10)&I5) | K5: =LEN(J5)
A6: 3 | B6: sustain | C6: Main | D6: status · making · features + beneficiary · action | E6: =Lines!$C$8 | F6: =Inputs!$B$65 | G6: =Lines!$C$15&IF(Inputs!$B$57="",""," "&Lines!$C$16) | H6: =IF(Inputs!$B$18="draw",Lines!$C$18,Lines!$C$17) | I6: ="" | J6: =E6&IF(F6="","",CHAR(10)&CHAR(10)&F6)&IF(G6="","",CHAR(10)&CHAR(10)&G6)&IF(H6="","",CHAR(10)&CHAR(10)&H6) | K6: =LEN(J6)
A7: 4 | B7: sustain, the artist's words | C7: Main | D7: quote · status · features + beneficiary · action | E7: =IF(Inputs!$B$43="","(no quote given, post skipped)",Lines!$C$9) | F7: =IF(Inputs!$B$43="","",Lines!$C$10) | G7: =IF(Inputs!$B$43="","",Lines!$C$15&IF(Inputs!$B$57="",""," "&Lines!$C$16)) | H7: =IF(Inputs!$B$43="","",IF(Inputs!$B$18="draw",Lines!$C$18,Lines!$C$17)) | I7: ="" | J7: =IF(Inputs!$B$43="","(no quote given, post skipped)",E7&IF(F7="","",CHAR(10)&CHAR(10)&F7)&IF(G7="","",CHAR(10)&CHAR(10)&G7)&IF(H7="","",CHAR(10)&CHAR(10)&H7)) | K7: =LEN(J7)
A8: 5 | B8: live (timed only) | C8: Main + Insiders | D8: status · features + beneficiary · action | E8: =IF(Inputs!$B$18="draw","(not used for a draw)",Lines!$C$11) | F8: ="" | G8: =IF(Inputs!$B$18="draw","",Lines!$C$15&IF(Inputs!$B$57="",""," "&Lines!$C$16)) | H8: =IF(Inputs!$B$18="draw","",IF(Inputs!$B$18="draw",Lines!$C$20,Lines!$C$19)) | I8: ="" | J8: =IF(Inputs!$B$18="draw","(not used for a draw)",E8&IF(G8="","",CHAR(10)&CHAR(10)&G8)&IF(H8="","",CHAR(10)&CHAR(10)&H8)) | K8: =LEN(J8)
A9: 6 | B9: still time (timed only) | C9: Main + Insiders (the plan's Halfway through) | D9: status · features + beneficiary · action | E9: =IF(Inputs!$B$18="draw","(not used for a draw)",Lines!$C$12) | F9: ="" | G9: =IF(Inputs!$B$18="draw","",Lines!$C$15&IF(Inputs!$B$57="",""," "&Lines!$C$16)) | H9: =IF(Inputs!$B$18="draw","",IF(Inputs!$B$18="draw",Lines!$C$20,Lines!$C$19)) | I9: ="" | J9: =IF(Inputs!$B$18="draw","(not used for a draw)",E9&IF(G9="","",CHAR(10)&CHAR(10)&G9)&IF(H9="","",CHAR(10)&CHAR(10)&H9)) | K9: =LEN(J9)
A10: 7 | B10: last chance | C10: Main | D10: status · features + beneficiary · action | E10: =IF(Inputs!$B$18="draw",Lines!$C$14,Lines!$C$13) | F10: ="" | G10: =Lines!$C$15&IF(Inputs!$B$57="",""," "&Lines!$C$16) | H10: =IF(Inputs!$B$18="draw",Lines!$C$20,Lines!$C$19) | I10: ="" | J10: =E10&IF(G10="","",CHAR(10)&CHAR(10)&G10)&IF(H10="","",CHAR(10)&CHAR(10)&H10) | K10: =LEN(J10)

Sheet Tweets
A1: The tweets, assembled
A2: The post's status line with the X handle, the hook on the announcement only, the beneficiary named once, and an action line that ends with the link. No features line, no hashtag, no bio. The announcement runs over X's limit until the tool cuts its hook.
A3: # | B3: Tweet | C3: Made of | D3: Status line | E3: Substance | F3: Beneficiary line | G3: Action line | H3: Tweet | I3: Characters
A4: 1 | B4: coming soon | C4: status · action | D4: =Lines!$C$24 | E4: ="" | F4: ="" | G4: =Lines!$C$25 | H4: =D4&IF(G4="","",CHAR(10)&CHAR(10)&G4) | I4: =LEN(H4)
A5: 2 | B5: announce | C5: status, with the beneficiary · hook · action | D5: =IF(Inputs!$B$14<>"",Lines!$C$27,Lines!$C$26) | E5: =Inputs!$B$36 | F5: ="" | G5: =IF(Inputs!$B$18="draw",Lines!$C$29,Lines!$C$28) | H5: =D5&IF(E5="","",CHAR(10)&CHAR(10)&E5)&IF(G5="","",CHAR(10)&CHAR(10)&G5) | I5: =LEN(H5)
A6: 3 | B6: live (timed only) | C6: status · action | D6: =IF(Inputs!$B$18="draw","(not used for a draw)",SUBSTITUTE(Lines!$C$11,Inputs!$B$46,Inputs!$B$47)) | E6: ="" | F6: ="" | G6: =IF(Inputs!$B$18="draw","",IF(Inputs!$B$18="draw",Lines!$C$29,Lines!$C$30)) | H6: =IF(Inputs!$B$18="draw","(not used for a draw)",D6&IF(G6="","",CHAR(10)&CHAR(10)&G6)) | I6: =LEN(H6)
A7: 4 | B7: still time (timed only) | C7: status · action | D7: =IF(Inputs!$B$18="draw","(not used for a draw)",SUBSTITUTE(Lines!$C$12,Inputs!$B$46,Inputs!$B$47)) | E7: ="" | F7: ="" | G7: =IF(Inputs!$B$18="draw","",IF(Inputs!$B$18="draw",Lines!$C$29,Lines!$C$30)) | H7: =IF(Inputs!$B$18="draw","(not used for a draw)",D7&IF(G7="","",CHAR(10)&CHAR(10)&G7)) | I7: =LEN(H7)
A8: 5 | B8: last chance | C8: status · action | D8: =IF(Inputs!$B$18="draw",SUBSTITUTE(Lines!$C$14,Inputs!$B$46,Inputs!$B$47),SUBSTITUTE(Lines!$C$13,Inputs!$B$46,Inputs!$B$47)) | E8: ="" | F8: ="" | G8: =IF(Inputs!$B$18="draw",Lines!$C$29,Lines!$C$30) | H8: =D8&IF(G8="","",CHAR(10)&CHAR(10)&G8) | I8: =LEN(H8)

Sheet Emails
A1: The emails, assembled
A2: Every cell below is a formula over Inputs and Lines. Body paragraphs are the fixed sentences with the same hook, making and quote dropped in. The 'Used?' column says when a row does not apply to this release.
A3: # | B3: Email (comms plan name) | C3: For | D3: Used? | E3: Subject | F3: Preview | G3: Kicker | H3: Headline | I3: Body | J3: CTA | K3: Card | L3: Quote | M3: Footer | N3: Full email, ready to paste | O3: Characters
A4: 1 | B4: Announcement (TL Non-flow) · Announcement (LE) | C4: both | D4: ="yes" | E4: =IF($D4<>"yes","",Lines!$C$40) | F4: =IF($D4<>"yes","",IF(Inputs!$B$18="draw","Enter the draw for a chance to collect. Closes "&Inputs!$B$70&".","Launching "&Inputs!$B$66&". Register for updates.")) | G4: =IF($D4<>"yes","",IF(Inputs!$B$18="draw","Enter the draw","Launching "&Inputs!$B$66)) | H4: =IF($D4<>"yes","",IF(Inputs!$B$18="draw",Inputs!$B$53,Inputs!$B$53&" by "&Inputs!$B$4)) | I4: =IF($D4<>"yes","",(IF(Inputs!$B$38="",Lines!$C$41,Inputs!$B$38)&IF(Inputs!$B$36="","",CHAR(10)&CHAR(10)&Inputs!$B$36)&IF(Inputs!$B$64="","",CHAR(10)&CHAR(10)&Inputs!$B$64)&IF(IF(OR(Inputs!$B$38="",Inputs!$B$60),Inputs!$B$62,Inputs!$B$63)="","",CHAR(10)&CHAR(10)&IF(OR(Inputs!$B$38="",Inputs!$B$60),Inputs!$B$62,Inputs!$B$63))&IF(IF(Inputs!$B$18="draw",Lines!$C$34,(Lines!$C$42&IF(Lines!$C$43="","",CHAR(10)&CHAR(10)&Lines!$C$43)))="","",CHAR(10)&CHAR(10)&IF(Inputs!$B$18="draw",Lines!$C$34,(Lines!$C$42&IF(Lines!$C$43="","",CHAR(10)&CHAR(10)&Lines!$C$43)))))) | J4: =IF($D4<>"yes","",IF(Inputs!$B$18="draw","Enter the draw","Discover the collaboration")) | K4: =IF($D4<>"yes","",Inputs!$B$77) | L4: =IF($D4<>"yes","",Inputs!$B$78) | M4: =IF($D4<>"yes","",IF(Inputs!$B$18="draw","Collect "&Inputs!$B$74,"Launching "&Inputs!$B$66)) | N4: =IF(D4<>"yes",D4,IF(E4="","","Subject: "&E4)&IF(F4="","",CHAR(10)&"Preview: "&F4)&IF(G4="","",CHAR(10)&"Kicker: "&G4)&IF(H4="","",CHAR(10)&"Headline: "&H4)&IF(I4="","",IF(E4&F4&G4&H4="","",CHAR(10)&CHAR(10))&I4)&IF(J4="","",CHAR(10)&CHAR(10)&"CTA: "&J4)&IF(K4="","",CHAR(10)&CHAR(10)&"Card: "&K4)&IF(L4="","",CHAR(10)&CHAR(10)&"Quote: "&L4)&IF(M4="","",CHAR(10)&CHAR(10)&"Footer: "&M4)) | O4: =LEN(N4)
A5: 2 | B5: Welcome (TL Flow) | C5: timed | D5: =IF(Inputs!$B$18="draw","(not used for a draw)","yes") | E5: =IF($D5<>"yes","","Welcome to Avant Arte") | F5: =IF($D5<>"yes","","Where the art world is more accessible.") | G5: ="" | H5: ="" | I5: =IF($D5<>"yes","",(Lines!$C$45&IF(Lines!$C$46="","",CHAR(10)&CHAR(10)&Lines!$C$46)&IF(Lines!$C$47="","",CHAR(10)&CHAR(10)&Lines!$C$47)&IF(Lines!$C$48="","",CHAR(10)&CHAR(10)&Lines!$C$48))) | J5: =IF($D5<>"yes","","Complete collector profile") | K5: ="" | L5: ="" | M5: =IF($D5<>"yes","","Where the art world is more accessible") | N5: =IF(D5<>"yes",D5,IF(E5="","","Subject: "&E5)&IF(F5="","",CHAR(10)&"Preview: "&F5)&IF(G5="","",CHAR(10)&"Kicker: "&G5)&IF(H5="","",CHAR(10)&"Headline: "&H5)&IF(I5="","",IF(E5&F5&G5&H5="","",CHAR(10)&CHAR(10))&I5)&IF(J5="","",CHAR(10)&CHAR(10)&"CTA: "&J5)&IF(K5="","",CHAR(10)&CHAR(10)&"Card: "&K5)&IF(L5="","",CHAR(10)&CHAR(10)&"Quote: "&L5)&IF(M5="","",CHAR(10)&CHAR(10)&"Footer: "&M5)) | O5: =LEN(N5)
A6: 3 | B6: Early Access (TL Flow) | C6: timed | D6: =IF(Inputs!$B$18="draw","(not used for a draw)","yes") | E6: =IF($D6<>"yes","",Inputs!$B$4&" – Early access 🔓") | F6: =IF($D6<>"yes","","Collect 24 hours before everyone else.") | G6: ="" | H6: ="" | I6: =IF($D6<>"yes","",(Lines!$C$32&IF(Lines!$C$50="","",CHAR(10)&CHAR(10)&Lines!$C$50)&IF(Inputs!$B$36="","",CHAR(10)&CHAR(10)&Inputs!$B$36)&IF(Inputs!$B$63="","",CHAR(10)&CHAR(10)&Inputs!$B$63)&IF(Lines!$C$51="","",CHAR(10)&CHAR(10)&Lines!$C$51)&IF(IF(Inputs!$B$26="","",Lines!$C$37)="","",CHAR(10)&CHAR(10)&IF(Inputs!$B$26="","",Lines!$C$37))&IF(Lines!$C$53="","",CHAR(10)&CHAR(10)&Lines!$C$53))) | J6: =IF($D6<>"yes","","Unlock early access") | K6: ="" | L6: ="" | M6: =IF($D6<>"yes","","24 hours ahead of the public launch") | N6: =IF(D6<>"yes",D6,IF(E6="","","Subject: "&E6)&IF(F6="","",CHAR(10)&"Preview: "&F6)&IF(G6="","",CHAR(10)&"Kicker: "&G6)&IF(H6="","",CHAR(10)&"Headline: "&H6)&IF(I6="","",IF(E6&F6&G6&H6="","",CHAR(10)&CHAR(10))&I6)&IF(J6="","",CHAR(10)&CHAR(10)&"CTA: "&J6)&IF(K6="","",CHAR(10)&CHAR(10)&"Card: "&K6)&IF(L6="","",CHAR(10)&CHAR(10)&"Quote: "&L6)&IF(M6="","",CHAR(10)&CHAR(10)&"Footer: "&M6)) | O6: =LEN(N6)
A7: 4 | B7: Early access (TL Artist PP Non Flow) | C7: timed | D7: =IF(Inputs!$B$18="draw","(not used for a draw)","yes") | E7: =IF($D7<>"yes","",Inputs!$B$4&" – Early access for past collectors") | F7: =IF($D7<>"yes","","Order before everyone else.") | G7: ="" | H7: ="" | I7: =IF($D7<>"yes","",(Lines!$C$32&IF(Lines!$C$50="","",CHAR(10)&CHAR(10)&Lines!$C$50)&IF(Inputs!$B$36="","",CHAR(10)&CHAR(10)&Inputs!$B$36)&IF(Inputs!$B$63="","",CHAR(10)&CHAR(10)&Inputs!$B$63)&IF(Lines!$C$52="","",CHAR(10)&CHAR(10)&Lines!$C$52)&IF(Lines!$C$53="","",CHAR(10)&CHAR(10)&Lines!$C$53)&IF(Lines!$C$35="","",CHAR(10)&CHAR(10)&Lines!$C$35)&IF(Lines!$C$33="","",CHAR(10)&CHAR(10)&Lines!$C$33))) | J7: =IF($D7<>"yes","","Unlock early access") | K7: =IF($D7<>"yes","",Inputs!$B$77) | L7: ="" | M7: =IF($D7<>"yes","","24 hours ahead of the public launch") | N7: =IF(D7<>"yes",D7,IF(E7="","","Subject: "&E7)&IF(F7="","",CHAR(10)&"Preview: "&F7)&IF(G7="","",CHAR(10)&"Kicker: "&G7)&IF(H7="","",CHAR(10)&"Headline: "&H7)&IF(I7="","",IF(E7&F7&G7&H7="","",CHAR(10)&CHAR(10))&I7)&IF(J7="","",CHAR(10)&CHAR(10)&"CTA: "&J7)&IF(K7="","",CHAR(10)&CHAR(10)&"Card: "&K7)&IF(L7="","",CHAR(10)&CHAR(10)&"Quote: "&L7)&IF(M7="","",CHAR(10)&CHAR(10)&"Footer: "&M7)) | O7: =LEN(N7)
A8: 5 | B8: Early Access (TL Insiders) · Early Access (LE Insiders), signed by the advisor | C8: both | D8: ="yes" | E8: =IF($D8<>"yes","",Inputs!$B$4&" – Early access for Insiders 🔓") | F8: =IF($D8<>"yes","",IF(Inputs!$B$18="draw","A first look, plus early access to a limited number of pre-orders.","Collect 24 hours before everyone else.")) | G8: ="" | H8: ="" | I8: =IF($D8<>"yes","",(Lines!$C$32&IF(Lines!$C$57="","",CHAR(10)&CHAR(10)&Lines!$C$57)&IF(Inputs!$B$36="","",CHAR(10)&CHAR(10)&Inputs!$B$36)&IF(IF(Inputs!$B$18="draw",Lines!$C$58,Lines!$C$59)="","",CHAR(10)&CHAR(10)&IF(Inputs!$B$18="draw",Lines!$C$58,Lines!$C$59))&IF(IF(Inputs!$B$18="draw",Lines!$C$60,Lines!$C$61)="","",CHAR(10)&CHAR(10)&IF(Inputs!$B$18="draw",Lines!$C$60,Lines!$C$61))&IF(Lines!$C$33="","",CHAR(10)&CHAR(10)&Lines!$C$33)&IF(Lines!$C$62="","",CHAR(10)&CHAR(10)&Lines!$C$62))) | J8: =IF($D8<>"yes","","Unlock early access") | K8: =IF($D8<>"yes","",Inputs!$B$77) | L8: ="" | M8: =IF($D8<>"yes","",IF(Inputs!$B$18="draw","Especially for you.","24 hours ahead of the public launch")) | N8: =IF(D8<>"yes",D8,IF(E8="","","Subject: "&E8)&IF(F8="","",CHAR(10)&"Preview: "&F8)&IF(G8="","",CHAR(10)&"Kicker: "&G8)&IF(H8="","",CHAR(10)&"Headline: "&H8)&IF(I8="","",IF(E8&F8&G8&H8="","",CHAR(10)&CHAR(10))&I8)&IF(J8="","",CHAR(10)&CHAR(10)&"CTA: "&J8)&IF(K8="","",CHAR(10)&CHAR(10)&"Card: "&K8)&IF(L8="","",CHAR(10)&CHAR(10)&"Quote: "&L8)&IF(M8="","",CHAR(10)&CHAR(10)&"Footer: "&M8)) | O8: =LEN(N8)
A9: 6 | B9: Early/Exclusive access (LE) | C9: draw | D9: =IF(Inputs!$B$18="draw","yes","(not used for a timed edition)") | E9: =IF($D9<>"yes","",Inputs!$B$4&" – Early access 🔓") | F9: =IF($D9<>"yes","","A first look, plus access to a limited number of pre-orders.") | G9: ="" | H9: ="" | I9: =IF($D9<>"yes","",(Lines!$C$32&IF(Lines!$C$54="","",CHAR(10)&CHAR(10)&Lines!$C$54)&IF(Inputs!$B$36="","",CHAR(10)&CHAR(10)&Inputs!$B$36)&IF(Lines!$C$55="","",CHAR(10)&CHAR(10)&Lines!$C$55)&IF(Lines!$C$56="","",CHAR(10)&CHAR(10)&Lines!$C$56)&IF(Lines!$C$35="","",CHAR(10)&CHAR(10)&Lines!$C$35)&IF(Lines!$C$33="","",CHAR(10)&CHAR(10)&Lines!$C$33))) | J9: =IF($D9<>"yes","","Unlock early access") | K9: =IF($D9<>"yes","",Inputs!$B$77) | L9: ="" | M9: =IF($D9<>"yes","","Especially for you.") | N9: =IF(D9<>"yes",D9,IF(E9="","","Subject: "&E9)&IF(F9="","",CHAR(10)&"Preview: "&F9)&IF(G9="","",CHAR(10)&"Kicker: "&G9)&IF(H9="","",CHAR(10)&"Headline: "&H9)&IF(I9="","",IF(E9&F9&G9&H9="","",CHAR(10)&CHAR(10))&I9)&IF(J9="","",CHAR(10)&CHAR(10)&"CTA: "&J9)&IF(K9="","",CHAR(10)&CHAR(10)&"Card: "&K9)&IF(L9="","",CHAR(10)&CHAR(10)&"Quote: "&L9)&IF(M9="","",CHAR(10)&CHAR(10)&"Footer: "&M9)) | O9: =LEN(N9)
A10: 7 | B10: Now Live (TL Flow) · Now Live (TL Non-flow) | C10: timed | D10: =IF(Inputs!$B$18="draw","(not used for a draw)","yes") | E10: =IF($D10<>"yes","",Inputs!$B$4&" – Available now, for "&Inputs!$B$19&" only") | F10: =IF($D10<>"yes","",Inputs!$B$76&", starting now.") | G10: =IF($D10<>"yes","",Lines!$C$36) | H10: =IF($D10<>"yes","",Inputs!$B$76&", starting now") | I10: =IF($D10<>"yes","",(Lines!$C$64&IF(Inputs!$B$36="","",CHAR(10)&CHAR(10)&Inputs!$B$36)&IF(Inputs!$B$64="","",CHAR(10)&CHAR(10)&Inputs!$B$64)&IF(Inputs!$B$63="","",CHAR(10)&CHAR(10)&Inputs!$B$63)&IF(Lines!$C$65="","",CHAR(10)&CHAR(10)&Lines!$C$65)&IF(IF(Inputs!$B$26="","",Lines!$C$37)="","",CHAR(10)&CHAR(10)&IF(Inputs!$B$26="","",Lines!$C$37)))) | J10: =IF($D10<>"yes","","Buy now") | K10: =IF($D10<>"yes","",Inputs!$B$77) | L10: =IF($D10<>"yes","",Inputs!$B$78) | M10: =IF($D10<>"yes","","Collect "&Inputs!$B$74) | N10: =IF(D10<>"yes",D10,IF(E10="","","Subject: "&E10)&IF(F10="","",CHAR(10)&"Preview: "&F10)&IF(G10="","",CHAR(10)&"Kicker: "&G10)&IF(H10="","",CHAR(10)&"Headline: "&H10)&IF(I10="","",IF(E10&F10&G10&H10="","",CHAR(10)&CHAR(10))&I10)&IF(J10="","",CHAR(10)&CHAR(10)&"CTA: "&J10)&IF(K10="","",CHAR(10)&CHAR(10)&"Card: "&K10)&IF(L10="","",CHAR(10)&CHAR(10)&"Quote: "&L10)&IF(M10="","",CHAR(10)&CHAR(10)&"Footer: "&M10)) | O10: =LEN(N10)
A11: 8 | B11: Halfway (TL Flow) | C11: timed, 48 hours | D11: =IF(Inputs!$B$18="draw","(not used for a draw)",IF(Inputs!$B$19="48 hours","yes","(48-hour windows only; a one-week window gets the 5 days and 3 days emails)")) | E11: =IF($D11<>"yes","",Inputs!$B$4&" – 24 hours to go") | F11: ="" | G11: =IF($D11<>"yes","",Lines!$C$36) | H11: =IF($D11<>"yes","",Lines!$C$66) | I11: ="" | J11: =IF($D11<>"yes","","Buy now") | K11: ="" | L11: ="" | M11: =IF($D11<>"yes","",Lines!$C$67) | N11: =IF(D11<>"yes",D11,IF(E11="","","Subject: "&E11)&IF(F11="","",CHAR(10)&"Preview: "&F11)&IF(G11="","",CHAR(10)&"Kicker: "&G11)&IF(H11="","",CHAR(10)&"Headline: "&H11)&IF(I11="","",IF(E11&F11&G11&H11="","",CHAR(10)&CHAR(10))&I11)&IF(J11="","",CHAR(10)&CHAR(10)&"CTA: "&J11)&IF(K11="","",CHAR(10)&CHAR(10)&"Card: "&K11)&IF(L11="","",CHAR(10)&CHAR(10)&"Quote: "&L11)&IF(M11="","",CHAR(10)&CHAR(10)&"Footer: "&M11)) | O11: =LEN(N11)
A12: 9 | B12: 5 days to go (TL Flow) | C12: timed, one week | D12: =IF(Inputs!$B$18="draw","(not used for a draw)",IF(Inputs!$B$19="48 hours","(one-week windows only; a 48-hour window gets the halfway email)","yes")) | E12: =IF($D12<>"yes","",Inputs!$B$4&" – 5 days left") | F12: ="" | G12: =IF($D12<>"yes","",Lines!$C$36) | H12: =IF($D12<>"yes","",Lines!$C$68) | I12: ="" | J12: =IF($D12<>"yes","","Buy "&Inputs!$B$49) | K12: ="" | L12: ="" | M12: =IF($D12<>"yes","",Lines!$C$72) | N12: =IF(D12<>"yes",D12,IF(E12="","","Subject: "&E12)&IF(F12="","",CHAR(10)&"Preview: "&F12)&IF(G12="","",CHAR(10)&"Kicker: "&G12)&IF(H12="","",CHAR(10)&"Headline: "&H12)&IF(I12="","",IF(E12&F12&G12&H12="","",CHAR(10)&CHAR(10))&I12)&IF(J12="","",CHAR(10)&CHAR(10)&"CTA: "&J12)&IF(K12="","",CHAR(10)&CHAR(10)&"Card: "&K12)&IF(L12="","",CHAR(10)&CHAR(10)&"Quote: "&L12)&IF(M12="","",CHAR(10)&CHAR(10)&"Footer: "&M12)) | O12: =LEN(N12)
A13: 10 | B13: 3 days to go (TL Flow) | C13: timed, one week | D13: =IF(Inputs!$B$18="draw","(not used for a draw)",IF(Inputs!$B$19="48 hours","(one-week windows only; a 48-hour window gets the halfway email)","yes")) | E13: =IF($D13<>"yes","",Inputs!$B$4&" – 3 days to go") | F13: ="" | G13: =IF($D13<>"yes","",Inputs!$B$53&" by "&Inputs!$B$4) | H13: =IF($D13<>"yes","",Lines!$C$69) | I13: =IF($D13<>"yes","",(Lines!$C$70&IF(Inputs!$B$36="","",CHAR(10)&CHAR(10)&Inputs!$B$36)&IF(Lines!$C$71="","",CHAR(10)&CHAR(10)&Lines!$C$71)&IF(IF(Inputs!$B$26="","",Lines!$C$38)="","",CHAR(10)&CHAR(10)&IF(Inputs!$B$26="","",Lines!$C$38)))) | J13: =IF($D13<>"yes","","Buy "&Inputs!$B$49) | K13: =IF($D13<>"yes","",Inputs!$B$77) | L13: ="" | M13: =IF($D13<>"yes","",Lines!$C$72) | N13: =IF(D13<>"yes",D13,IF(E13="","","Subject: "&E13)&IF(F13="","",CHAR(10)&"Preview: "&F13)&IF(G13="","",CHAR(10)&"Kicker: "&G13)&IF(H13="","",CHAR(10)&"Headline: "&H13)&IF(I13="","",IF(E13&F13&G13&H13="","",CHAR(10)&CHAR(10))&I13)&IF(J13="","",CHAR(10)&CHAR(10)&"CTA: "&J13)&IF(K13="","",CHAR(10)&CHAR(10)&"Card: "&K13)&IF(L13="","",CHAR(10)&CHAR(10)&"Quote: "&L13)&IF(M13="","",CHAR(10)&CHAR(10)&"Footer: "&M13)) | O13: =LEN(N13)
A14: 11 | B14: Last chance (TL Flow) · Last chance (LE) | C14: both | D14: ="yes" | E14: =IF($D14<>"yes","",Inputs!$B$4&" – Last chance to "&IF(Inputs!$B$18="draw","enter the draw","collect")) | F14: =IF($D14<>"yes","",IF(Inputs!$B$18="draw","The draw closes at "&Inputs!$B$71&" on "&Inputs!$B$70&".","Time is almost up.")) | G14: =IF($D14<>"yes","",Inputs!$B$4) | H14: =IF($D14<>"yes","",IF(Inputs!$B$18="draw","Last chance to enter the draw","Last chance to collect")) | I14: =IF($D14<>"yes","",IF(Inputs!$B$18="draw",(Lines!$C$76&IF(Inputs!$B$36="","",CHAR(10)&CHAR(10)&Inputs!$B$36)&IF(Lines!$C$77="","",CHAR(10)&CHAR(10)&Lines!$C$77)),(Lines!$C$74&IF(Lines!$C$75="","",CHAR(10)&CHAR(10)&Lines!$C$75)&IF(IF(Inputs!$B$26="","",Lines!$C$38)="","",CHAR(10)&CHAR(10)&IF(Inputs!$B$26="","",Lines!$C$38))))) | J14: =IF($D14<>"yes","",IF(Inputs!$B$18="draw","Enter the draw","Buy now")) | K14: =IF($D14<>"yes","",Inputs!$B$77) | L14: ="" | M14: =IF($D14<>"yes","","Time is almost up") | N14: =IF(D14<>"yes",D14,IF(E14="","","Subject: "&E14)&IF(F14="","",CHAR(10)&"Preview: "&F14)&IF(G14="","",CHAR(10)&"Kicker: "&G14)&IF(H14="","",CHAR(10)&"Headline: "&H14)&IF(I14="","",IF(E14&F14&G14&H14="","",CHAR(10)&CHAR(10))&I14)&IF(J14="","",CHAR(10)&CHAR(10)&"CTA: "&J14)&IF(K14="","",CHAR(10)&CHAR(10)&"Card: "&K14)&IF(L14="","",CHAR(10)&CHAR(10)&"Quote: "&L14)&IF(M14="","",CHAR(10)&CHAR(10)&"Footer: "&M14)) | O14: =LEN(N14)
A15: 12 | B15: First-time collector survey (LE) | C15: draw, after the draw closes | D15: =IF(Inputs!$B$18="draw","yes","(not used for a timed edition)") | E15: =IF($D15<>"yes","",Lines!$C$79) | F15: ="" | G15: ="" | H15: ="" | I15: =IF($D15<>"yes","",(Lines!$C$32&IF(Lines!$C$80="","",CHAR(10)&CHAR(10)&Lines!$C$80)&IF(Lines!$C$81="","",CHAR(10)&CHAR(10)&Lines!$C$81)&IF(Lines!$C$82="","",CHAR(10)&CHAR(10)&Lines!$C$82)&IF(Lines!$C$83="","",CHAR(10)&CHAR(10)&Lines!$C$83))) | J15: =IF($D15<>"yes","","Complete survey") | K15: =IF($D15<>"yes","",Inputs!$B$4) | L15: ="" | M15: ="" | N15: =IF(D15<>"yes",D15,IF(E15="","","Subject: "&E15)&IF(F15="","",CHAR(10)&"Preview: "&F15)&IF(G15="","",CHAR(10)&"Kicker: "&G15)&IF(H15="","",CHAR(10)&"Headline: "&H15)&IF(I15="","",IF(E15&F15&G15&H15="","",CHAR(10)&CHAR(10))&I15)&IF(J15="","",CHAR(10)&CHAR(10)&"CTA: "&J15)&IF(K15="","",CHAR(10)&CHAR(10)&"Card: "&K15)&IF(L15="","",CHAR(10)&CHAR(10)&"Quote: "&L15)&IF(M15="","",CHAR(10)&CHAR(10)&"Footer: "&M15)) | O15: =LEN(N15)
A16: 13 | B16: Non-purchaser survey (LE) | C16: draw, after the draw closes | D16: =IF(Inputs!$B$18="draw","yes","(not used for a timed edition)") | E16: =IF($D16<>"yes","",Inputs!$B$4&" – Any feedback?") | F16: ="" | G16: =IF($D16<>"yes","","Your feedback") | H16: =IF($D16<>"yes","",Inputs!$B$4) | I16: =IF($D16<>"yes","",(Lines!$C$84&IF(Lines!$C$85="","",CHAR(10)&CHAR(10)&Lines!$C$85)&IF(Lines!$C$86="","",CHAR(10)&CHAR(10)&Lines!$C$86)&IF(Lines!$C$87="","",CHAR(10)&CHAR(10)&Lines!$C$87))) | J16: =IF($D16<>"yes","","Complete survey") | K16: ="" | L16: ="" | M16: =IF($D16<>"yes","",Lines!$C$88) | N16: =IF(D16<>"yes",D16,IF(E16="","","Subject: "&E16)&IF(F16="","",CHAR(10)&"Preview: "&F16)&IF(G16="","",CHAR(10)&"Kicker: "&G16)&IF(H16="","",CHAR(10)&"Headline: "&H16)&IF(I16="","",IF(E16&F16&G16&H16="","",CHAR(10)&CHAR(10))&I16)&IF(J16="","",CHAR(10)&CHAR(10)&"CTA: "&J16)&IF(K16="","",CHAR(10)&CHAR(10)&"Card: "&K16)&IF(L16="","",CHAR(10)&CHAR(10)&"Quote: "&L16)&IF(M16="","",CHAR(10)&CHAR(10)&"Footer: "&M16)) | O16: =LEN(N16)
A17: 14 | B17: Monthly Preview · this release's paragraph | C17: both; the advisor's monthly email is one paragraph per release, this is this release's | D17: ="yes" | E17: ="" | F17: ="" | G17: ="" | H17: ="" | I17: =IF($D17<>"yes","",(Lines!$C$90&IF(Inputs!$B$36="","",CHAR(10)&CHAR(10)&Inputs!$B$36)&IF(Inputs!$B$64="","",CHAR(10)&CHAR(10)&Inputs!$B$64)&IF(IF(Inputs!$B$18="draw",Lines!$C$91,Lines!$C$92)="","",CHAR(10)&CHAR(10)&IF(Inputs!$B$18="draw",Lines!$C$91,Lines!$C$92)))) | J17: ="" | K17: ="" | L17: ="" | M17: ="" | N17: =IF(D17<>"yes",D17,IF(E17="","","Subject: "&E17)&IF(F17="","",CHAR(10)&"Preview: "&F17)&IF(G17="","",CHAR(10)&"Kicker: "&G17)&IF(H17="","",CHAR(10)&"Headline: "&H17)&IF(I17="","",IF(E17&F17&G17&H17="","",CHAR(10)&CHAR(10))&I17)&IF(J17="","",CHAR(10)&CHAR(10)&"CTA: "&J17)&IF(K17="","",CHAR(10)&CHAR(10)&"Card: "&K17)&IF(L17="","",CHAR(10)&CHAR(10)&"Quote: "&L17)&IF(M17="","",CHAR(10)&CHAR(10)&"Footer: "&M17)) | O17: =LEN(N17)

Sheet Rules
A1: The system on one page
A3: What it covers | B3: Every post on our own Instagram feed and the Insiders account, the tweets, and the emails in the comms plan: Announcement (TL and LE), Welcome, Early Access (TL Flow, TL Artist PP, Insiders TL and LE, LE early/exclusive), Now Live, Halfway, 5 days to go, 3 days to go, Last chance (TL and LE), the two LE surveys, and this release's paragraph for the Monthly Preview. The artist's own email is rare and stays hand-written.
A4: Skeleton, posts | B4: Every post is: status line, substance, features line, action line, and a hashtag on the announcement only. Coming Soon opens with the bio.
A5: Insiders | B5: The Insiders account posts the same caption as the main feed. The plan says which: Announcement, Now Live and Halfway for a timed edition, Announcement for a draw. The Channels column on Posts carries this. Stories are image-led and stay outside the sheet.
A6: Twitter | B6: A tweet is the post's status line with the X handle, the hook on the announcement only, the beneficiary named once, and an action line that ends with the link: sign up for updates, enter the draw, or buy a print. No features line, no hashtag, no bio. Same deadline form. Coming soon names the artist and not the work.
A7: Skeleton, emails | B7: Every email is: subject, preview, kicker, headline, body paragraphs, CTA, card, quote, footer. Bodies are fixed sentences from the Lines sheet with the same fragments dropped in. Halfway and 5 days to go have no body: they are image-led.
A8: The hook carries the voice | B8: The hook is where a release sounds like itself, and it can be as editorial as the writer likes: 'Folklore says a changeling is a child swapped at birth for something not quite human. Grayson Perry's version is the generation raised by screens, and he means it to disturb.' The one test is that it must read as well in the middle of an email as at the top of a post, because it appears in 16 slots and most of them are middle paragraphs. That rules out a sentence which assumes it is opening: a rhetorical question, or an aside about the artist that never describes the work.
A9: Naming the work | B9: The opener's tail is the title (single print only), the edition phrase, and the qualifier if one is written: 'The Changeling, a new limited edition print'; 'a quartet of new limited edition prints spanning five decades of the artist's career'; 'six new limited edition prints from his iconic Dream House series'. A pair or a quartet takes no title; the hook names the work. The same tail is used by the Insiders email, LE early access, Now Live and the Monthly Preview paragraph.
A10: Fragments | B10: Four per release, written once: bio (2 to 3 sentences, Coming Soon only), hook (2 to 3 sentences about the work, in every post and email), making (one sentence on how it was made), quote (verbatim). The hook and bio must not repeat each other.
A11: Voice | B11: Fragments never say we or our, and the making line says 'printmakers at Make-Ready' so the sheet can add 'our'. The hook may name the artist. The Insiders email and the first-time survey are signed by the advisor named on Inputs. Features never say 'our'.
A12: Who and what | B12: 'by {artist}' is always the artist. 'collaboration with {collab_with}' is the artist's name, or the estate. 'unit' is what one is called (print, embroidery, sculpture), and the sheet writes 'a print' or 'an embroidery' wherever a line names one.
A13: Features | B13: The standard three (signed by the artist, individually numbered, free worldwide shipping) plus anything bespoke: framed, a set offer, a partner credit. One line of short sentences in a post, a list in an email. The beneficiary follows, named once.
A14: Beneficiary | B14: One phrase everywhere: 'released in support of'. It goes in the opener unless the hook already names the beneficiary.
... A20: How to use | B20: Fill the blue cells on Inputs. Read Posts, Tweets and Emails. To change the house wording, edit the blue cells on Lines once.
